# Kotlin中的异常
`Kotlin`的异常处理和`Java`以及其他许多语言的处理方式相似。一个函数可以正常结束，也可以在出现错误的情况下抛出异常。方法的调用者能捕获到这个异常并处理它；如果没有被处理，异常会沿着调用栈再次抛出。

`Kotlin`中异常处理语句的基本形式和`Java`类似，抛出异常的方式也不例外：
```kotlin

if(percentage !in 0..100){
    throw IllegalArgumentException("A percentage value must be between 0 and 100: $percentage")
}
```
和其他所有的类一样，不必使用`new`关键字来创建异常实例。
和`Java`不同的是，`Kotlin`中`throw`结构是一个表达式，能作为另一个表达式的一部分使用：
```kotlin
val percentage = 
    if (number in 0..100)
        number
    else
        throw IllegalArgumentException("A percentage value must be between 0 and 100: $number") 
```

## try、catch和finally
和`Java`一样，使用带有`catch`和`finally`子句的`try`结构来处理异常：
```kotlin
import java.io.BufferedReader
import java.io.StringReader
import java.lang.NumberFormatException

fun readNumber(reader: BufferedReader): Int?{
    try {
        val line = reader.readLine();
        return Integer.parseInt(line)
    }catch (e: NumberFormatException){
        return null
    }finally {
        reader.close()
    }
}

fun main(args: Array<String>){
    val reader = BufferedReader(StringReader("239"))
    println(readNumber(reader))
}
```

和`Java`最大的区别就是`throws`子句没有出现在代码中：如果用`Java`来写这个函数，会显式地在函数声明后写上`throws IOException`。需要这样做的原因是`IOException`是一个受检异常.在`Java`中,这种异常必须显式地处理.必须声明你的函数能抛出的所有受检异常。如果调用另外一个函数,需要处理这个函数的受检异常,或者声明函数也能抛出这些异常。

和其他许多现代`JVM`语言一样,`Kotlin`并不区分受检异常和未受检异常.不用指定函数抛出的异常,而且可以处理也可以不处理异常。这种设计是基于`Java`中使用异常的实践做出的决定。经验显示这些`Java`规则常常导致许多毫无意义的重新抛出或者忽略异常的代码,而且这些规则不能总是保护免受可能发生的错误。

## try作为表达式
为了了解`Java`和`Kotlin`之间另外一个显著的差异,修改一下这个例子,去掉`finally`部分,并添加一些代码,用来打印从文件中读取的数字:

```kotlin
import java.io.BufferedReader
import java.io.StringReader
import java.lang.NumberFormatException

fun readNumber(reader: BufferedReader){
    val number = try {
        Integer.parseInt(reader.readLine())
    }catch (e: NumberFormatException){
        return
    }
    println(number)
}

fun main(args: Array<String>){
    val reader = BufferedReader(StringReader("239"))
    readNumber(reader)
}
```

`Kotlin`中的`try`关键字就像`if`和`when`一样,引入了一个表达式,可以把它的值赋给一个变量。不同于`if`,总是需要用花括号把语句主体括起来。和其它语句一样,如果其主体包含多个表达式,那么整个`try`表达式的值就是最后一个表达式的值。
这个例子将`return`语句放在`catch`代码块中,因此该函数的执行在`catch`代码块之后不会继续。如果想继续执行,`catch`子句也需要有一个值,它将是子句中最后一个表达式的值:
```kotlin
import java.io.BufferedReader
import java.io.StringReader
import java.lang.NumberFormatException

fun readNumber2(reader: BufferedReader){
    val number = try {
        Integer.parseInt(reader.readLine())
    }catch (e: NumberFormatException){
        null
    }
    println(number)
}


fun main(args: Array<String>){
    val reader = BufferedReader(StringReader("not a number"))
    readNumber2(reader)
}
```

如果一个`try`代码块执行一切正常,代码块中最后一个表达式就是结果。如果捕获到了一个异常,相应`catch`代码块中最后一个表达式就是结果。在这个例子中,如果捕获到了`NumberFormatException`,结果值就是`null`。

